<?xml version="1.0"?>
<robot name="line_block">

    <link name="line">
        <visual>
            <geometry>
                <cylinder radius="0.01" length="20.0"/>
            </geometry>
            <origin xyz="0 0 -2.5" rpy="0 1.57 0"/>
            <material name="red">
                <color rgba="1 0 0.2 1"/>
            </material>
        </visual>
        <collision>
            <geometry>
                <cylinder radius="0.01" length="20.0"/>
            </geometry>
            <origin xyz="0 0 -2.5" rpy="0 1.57 0"/>
        </collision>
        <inertial>
            <mass value="0"/>
            <inertia ixx="0.0" ixy="0.0" ixz="0.0" iyy="0.0" iyz="0.0" izz="0.0"/>
        </inertial>
    </link>

    <link name="block">
        <visual>
            <geometry>
                <sphere radius="0.5"/>
            </geometry>
            <origin xyz="0 0 0"/>
            <material name="blue">
                <color rgba="0 0 .8 1"/>
            </material>
        </visual>
        <collision>
            <geometry>
                <sphere radius="0.5"/>
            </geometry>
            <origin xyz="0 0 0"/>
        </collision>
        <inertial>
            <mass value="1"/>
            <inertia ixx="1.0" ixy="0.0" ixz="0.0" iyy="1.0" iyz="0.0" izz="1.0"/>
        </inertial>
    </link>

     <joint name="my_joint" type="prismatic">
        <origin xyz="0.0 0.0 1"/>
        <axis xyz="1.0 0.0 0.0" />
        <parent link="line"/>
        <child link="block"/>
        <limit />
     </joint>

</robot>
